[2023-01-24T16:26:13.176+0000] {taskinstance.py:1083} INFO - Dependencies all met for <TaskInstance: exercise15.read_users manual__2023-01-24T16:26:12.177685+00:00 [queued]>
[2023-01-24T16:26:13.183+0000] {taskinstance.py:1083} INFO - Dependencies all met for <TaskInstance: exercise15.read_users manual__2023-01-24T16:26:12.177685+00:00 [queued]>
[2023-01-24T16:26:13.184+0000] {taskinstance.py:1279} INFO - 
--------------------------------------------------------------------------------
[2023-01-24T16:26:13.184+0000] {taskinstance.py:1280} INFO - Starting attempt 1 of 1
[2023-01-24T16:26:13.185+0000] {taskinstance.py:1281} INFO - 
--------------------------------------------------------------------------------
[2023-01-24T16:26:13.194+0000] {taskinstance.py:1300} INFO - Executing <Task(_PythonDecoratedOperator): read_users> on 2023-01-24 16:26:12.177685+00:00
[2023-01-24T16:26:13.199+0000] {standard_task_runner.py:55} INFO - Started process 747 to run task
[2023-01-24T16:26:13.203+0000] {standard_task_runner.py:82} INFO - Running: ['***', 'tasks', 'run', 'exercise15', 'read_users', 'manual__2023-01-24T16:26:12.177685+00:00', '--job-id', '11', '--raw', '--subdir', 'DAGS_FOLDER/exercise15.py', '--cfg-path', '/tmp/tmpt5vyt65f']
[2023-01-24T16:26:13.204+0000] {standard_task_runner.py:83} INFO - Job 11: Subtask read_users
[2023-01-24T16:26:13.259+0000] {task_command.py:388} INFO - Running <TaskInstance: exercise15.read_users manual__2023-01-24T16:26:12.177685+00:00 [running]> on host 2ee7bc173f76
[2023-01-24T16:26:13.307+0000] {taskinstance.py:1509} INFO - Exporting the following env vars:
AIRFLOW_CTX_DAG_OWNER=***
AIRFLOW_CTX_DAG_ID=exercise15
AIRFLOW_CTX_TASK_ID=read_users
AIRFLOW_CTX_EXECUTION_DATE=2023-01-24T16:26:12.177685+00:00
AIRFLOW_CTX_TRY_NUMBER=1
AIRFLOW_CTX_DAG_RUN_ID=manual__2023-01-24T16:26:12.177685+00:00
[2023-01-24T16:26:13.309+0000] {taskinstance.py:1768} ERROR - Task failed with exception
Traceback (most recent call last):
  File "/home/airflow/.local/lib/python3.7/site-packages/airflow/decorators/base.py", line 217, in execute
    return_value = super().execute(context)
  File "/home/airflow/.local/lib/python3.7/site-packages/airflow/operators/python.py", line 175, in execute
    return_value = self.execute_callable()
  File "/home/airflow/.local/lib/python3.7/site-packages/airflow/operators/python.py", line 192, in execute_callable
    return self.python_callable(*self.op_args, **self.op_kwargs)
  File "/opt/airflow/dags/exercise15.py", line 36, in read_users
    with open(path, "r") as f:
FileNotFoundError: [Errno 2] No such file or directory: '.../dags/data/users.json'
[2023-01-24T16:26:13.318+0000] {taskinstance.py:1323} INFO - Marking task as FAILED. dag_id=exercise15, task_id=read_users, execution_date=20230124T162612, start_date=20230124T162613, end_date=20230124T162613
[2023-01-24T16:26:13.324+0000] {standard_task_runner.py:105} ERROR - Failed to execute job 11 for task read_users ([Errno 2] No such file or directory: '.../dags/data/users.json'; 747)
[2023-01-24T16:26:13.335+0000] {local_task_job.py:208} INFO - Task exited with return code 1
[2023-01-24T16:26:13.353+0000] {taskinstance.py:2578} INFO - 0 downstream tasks scheduled from follow-on schedule check
