[2023-01-24T16:22:29.331+0000] {taskinstance.py:1083} INFO - Dependencies all met for <TaskInstance: exercise15.read_users manual__2023-01-24T16:22:28.599735+00:00 [queued]>
[2023-01-24T16:22:29.337+0000] {taskinstance.py:1083} INFO - Dependencies all met for <TaskInstance: exercise15.read_users manual__2023-01-24T16:22:28.599735+00:00 [queued]>
[2023-01-24T16:22:29.337+0000] {taskinstance.py:1279} INFO - 
--------------------------------------------------------------------------------
[2023-01-24T16:22:29.338+0000] {taskinstance.py:1280} INFO - Starting attempt 1 of 1
[2023-01-24T16:22:29.339+0000] {taskinstance.py:1281} INFO - 
--------------------------------------------------------------------------------
[2023-01-24T16:22:29.347+0000] {taskinstance.py:1300} INFO - Executing <Task(_PythonDecoratedOperator): read_users> on 2023-01-24 16:22:28.599735+00:00
[2023-01-24T16:22:29.352+0000] {standard_task_runner.py:55} INFO - Started process 423 to run task
[2023-01-24T16:22:29.356+0000] {standard_task_runner.py:82} INFO - Running: ['***', 'tasks', 'run', 'exercise15', 'read_users', 'manual__2023-01-24T16:22:28.599735+00:00', '--job-id', '9', '--raw', '--subdir', 'DAGS_FOLDER/exercise15.py', '--cfg-path', '/tmp/tmpvyrnz457']
[2023-01-24T16:22:29.357+0000] {standard_task_runner.py:83} INFO - Job 9: Subtask read_users
[2023-01-24T16:22:29.406+0000] {task_command.py:388} INFO - Running <TaskInstance: exercise15.read_users manual__2023-01-24T16:22:28.599735+00:00 [running]> on host 2ee7bc173f76
[2023-01-24T16:22:29.452+0000] {taskinstance.py:1509} INFO - Exporting the following env vars:
AIRFLOW_CTX_DAG_OWNER=***
AIRFLOW_CTX_DAG_ID=exercise15
AIRFLOW_CTX_TASK_ID=read_users
AIRFLOW_CTX_EXECUTION_DATE=2023-01-24T16:22:28.599735+00:00
AIRFLOW_CTX_TRY_NUMBER=1
AIRFLOW_CTX_DAG_RUN_ID=manual__2023-01-24T16:22:28.599735+00:00
[2023-01-24T16:22:29.454+0000] {taskinstance.py:1768} ERROR - Task failed with exception
Traceback (most recent call last):
  File "/home/airflow/.local/lib/python3.7/site-packages/airflow/decorators/base.py", line 217, in execute
    return_value = super().execute(context)
  File "/home/airflow/.local/lib/python3.7/site-packages/airflow/operators/python.py", line 175, in execute
    return_value = self.execute_callable()
  File "/home/airflow/.local/lib/python3.7/site-packages/airflow/operators/python.py", line 192, in execute_callable
    return self.python_callable(*self.op_args, **self.op_kwargs)
  File "/opt/airflow/dags/exercise15.py", line 36, in read_users
    with open(path, "r") as f:
FileNotFoundError: [Errno 2] No such file or directory: './dags/data/users.json'
[2023-01-24T16:22:29.463+0000] {taskinstance.py:1323} INFO - Marking task as FAILED. dag_id=exercise15, task_id=read_users, execution_date=20230124T162228, start_date=20230124T162229, end_date=20230124T162229
[2023-01-24T16:22:29.473+0000] {standard_task_runner.py:105} ERROR - Failed to execute job 9 for task read_users ([Errno 2] No such file or directory: './dags/data/users.json'; 423)
[2023-01-24T16:22:29.488+0000] {local_task_job.py:208} INFO - Task exited with return code 1
[2023-01-24T16:22:29.517+0000] {taskinstance.py:2578} INFO - 0 downstream tasks scheduled from follow-on schedule check
